Workbook
Name Bandeiras: Outros!$C$2:$C$4
Name distribuidora: Tabela
Name Distribuidoras: #REF!
Name Distribuidoras: #REF!
Name Distribuidoras: #REF!
Name Distribuidoras: #REF!
Name Tabela: #REF!
Name Varejo: Outros!$C$2:$C$4

Sheet Simulador >>
A9: Simulador >>

Sheet Simulador Eco Circ Verde
B4: Simulador Economia Circular Verde - Ecoa
B6: SERVIÇOS FINANCEIROS | K6: RESUMO SERVIÇOS BANCÁRIOS
B8: Tipo de Estabelecimento | K8: Produtos | L8: Valor Transacional | M8: Resultado
B9: Comercio varejista de vestuário, acessórios, calçados, roupas íntimas, etc | K9: Maquininha Banco | L9: =C24 -> 26000 | M9: =C24-C25 -> 3204.0893
K10: Cartão de Crédito | L10: =C32 -> 5000 | M10: =L10*'Outros Serviços'!C3 -> 150
B11: MAQUININHA BANCO | K11: Outros Serviços | L11: =(C33*E33)+(C34*E34)+(C35*E35)+(C36*E36) -> 80.8 | M11: =((C33*E33)+(C34*E34)+(C35*E35)+(C36*E36))-((C33*'Outros Serviços'!D4)+(C34*'Outros Serviços'!D5)+(C35*'Outros Serviços'!D6)+(C36*'Outros Serviços'!D7)) -> 56.56
K12: Total | L12: =SUM(L9:L11) -> 31080.8 | M12: =SUM(M9:M11) -> 3410.6493
B13: Tipo de Plano | C13: Ecoa | K13: Resultado Total/Valor Transacional Total | M13: =M12/L12 -> 0.10973493
B15: Plano Antecipado? | C15: =IF(C13="Ecoa","Sim","Não") -> Sim | K15: MÉTRICAS DE IMPACTO E LOYALTY
B17: Bandeira mais utilizada na Maquininha | C17: Visa/Master | K17: Quantidade de Pontos Ecoa | M17: =ROUND(((I20*C20)+(I21*C21)+(C22*I22)+(C23*I23)+(C32*G32)+(C33*E33*G33)+(C34*E34*G34)+(C35*E35*G35)+(C36*E36*G36))/'Pontos Ecoa'!C2,0) -> 16444
K18: Impacto Ambiental (kg de Carbono) | M18: =M17*'Pontos Ecoa'!C3 -> 493.32
B19: Volume em R$ | E19: Qtd Parcelas (Média) | G19: Taxas | I19: Taxa Generosidade | K19: Impacto Social (Energia) | M19: =M17*'Pontos Ecoa'!C4 -> 328.88
B20: Débito | C20: 0 | G20: =IF($C$17="Hipercard","-",'Taxa Adquirência'!D2) -> 0.0101566 | I20: 0
B21: Crédito à Vista | C21: 1000 | G21: ='Taxa Adquirência'!D3 -> 0.0168586 | I21: ='Pontos Ecoa'!C7 -> 0.005 | K21: Meta de Sustentabilidade Mensal (kg Carbono) | M21: 100000
B22: Crédito Parcelado 2 x 6 | C22: 5000 | E22: 2 | G22: ='Taxa Adquirência'!D4 -> 0.02005 | I22: =VLOOKUP(E22,'Pontos Ecoa'!B7:C18,2,0) -> 0.0075
B23: Crédito Parcelado 7 x 12 | C23: 20000 | E23: 7 | G23: ='Taxa Adquirência'!D5 -> 0.0233372 | I23: =VLOOKUP(E23,'Pontos Ecoa'!B7:C18,2,0) -> 0.02 | K23: Resultado de Sustentabilidade (kg Carbono) | L23: 200 | M23: =M18*$L$23 -> 98664
B24: TPV Mensal | C24: =SUM(C20:C23) -> 26000
B25: Valor Líquido Estimado | C25: =Antecipação!M91 -> 22795.911 | K25: % Atingimento da Meta de Sustentabilidade | M25: =M23/M21 -> 0.98664
B27: Taxa de Antecipação | C27: 0.0299
B29: OUTROS SERVIÇOS - BANCO | K29: VISÃO DO CLIENTE
B31: Qtd. / Volume Utilizado | E31: Valor Unitário | G31: Taxa de Generosidade | K31: Valor Médio Mensal Conta de Luz | M31: 1000
B32: Cartão de Crédito | C32: 5000 | E32: - | G32: 0.01 | K32: Resgate dos Pontos Ecoa | M32: =-M19 -> -328.88
B33: Boleto Recarga | C33: 10 | E33: ='Outros Serviços'!C5 -> 3 | G33: 0.01 | K33: Nova Conta de Luz | M33: =M31+M32 -> 671.12
B34: Boleto Cobrança Liquidado | C34: 10 | E34: ='Outros Serviços'!C5 -> 3 | G34: 0.01 | K34: Economia % | M34: =1-(M33/M31) -> 0.32888
B35: TED | C35: 2 | E35: ='Outros Serviços'!C6 -> 5.9 | G35: 0.01
B36: Saque Banco 24Horas | C36: 1 | E36: ='Outros Serviços'!C7 -> 9 | G36: 0.01

Sheet Inputs >>
A9: Inputs >>

Sheet Pontos Ecoa
B2: Valor Pontos Ecoa | C2: 0.03
B3: kg Carbono por Ponto | C3: 0.03
B4: Créditos de Energia por Ponto | C4: 0.02
B6: generosidade adiq
B7: 1 | C7: 0.005
B8: 2 | C8: =C7+0.25% -> 0.0075
B9: 3 | C9: =C8+0.25% -> 0.01
B10: 4 | C10: =C9+0.25% -> 0.0125
B11: 5 | C11: =C10+0.25% -> 0.015
B12: 6 | C12: =C11+0.25% -> 0.0175
B13: 7 | C13: =C12+0.25% -> 0.02
B14: 8 | C14: =C13+0.25% -> 0.0225
B15: 9 | C15: =C14+0.25% -> 0.025
B16: 10 | C16: =C15+0.25% -> 0.0275
B17: 11 | C17: =C16+0.25% -> 0.03
B18: 12 | C18: =C17+0.25% -> 0.0325

Sheet Taxa Adquirência
B2: Débito | C2: =IF($C$10="Visa/Master",VLOOKUP($C$11,'Taxas Bandeira'!A:N,14,0),IF($C$10="Elo",VLOOKUP($C$11,'Taxas Bandeira'!A:N,3,0),IF($C$10="Hipercard",VLOOKUP($C$11,'Taxas Bandeira'!A:N,10,0),0))) -> 0.0081566 | D2: =C2+H2 -> 0.0101566 | E2: =IFERROR('Simulador Eco Circ Verde'!C20/'Simulador Eco Circ Verde'!$C$24,0) -> 0 | F2: 0 | G2: ='Simulador Eco Circ Verde'!C15 -> Sim | H2: =IF(C10="Hipercard",0%,0.2%) -> 0.002
B3: Crédito à Vista | C3: =IF($C$10="Visa/Master",VLOOKUP($C$11,'Taxas Bandeira'!A:N,13,0),IF($C$10="Elo",VLOOKUP($C$11,'Taxas Bandeira'!A:N,4,0),IF($C$10="Hipercard",VLOOKUP($C$11,'Taxas Bandeira'!A:N,9,0)))) -> 0.0168586 | D3: =IF($G$2="Sim",C3+0%,C3+H3) -> 0.0168586 | E3: =IFERROR('Simulador Eco Circ Verde'!C21/'Simulador Eco Circ Verde'!$C$24,0) -> 0.038461538 | F3: 1 | H3: =0.5% -> 0.005
B4: Crédito Parcelado 2 x 6 | C4: =IF($C$10="Visa/Master",VLOOKUP($C$11,'Taxas Bandeira'!A:N,11,0),IF($C$10="Elo",VLOOKUP($C$11,'Taxas Bandeira'!A:N,5,0),IF($C$10="Hipercard",VLOOKUP($C$11,'Taxas Bandeira'!A:N,7,0),0))) -> 0.02005 | D4: =IF($G$2="Sim",C4+0%,C4+H4) -> 0.02005 | E4: =IFERROR('Simulador Eco Circ Verde'!C22/'Simulador Eco Circ Verde'!$C$24,0) -> 0.19230769 | F4: ='Simulador Eco Circ Verde'!E22 -> 2 | H4: =0.5% -> 0.005
B5: Crédito Parcelado 7 x 12 | C5: =IF($C$10="Visa/Master",VLOOKUP($C$11,'Taxas Bandeira'!A:N,12,0),IF($C$10="Elo",VLOOKUP($C$11,'Taxas Bandeira'!A:N,6,0),IF($C$10="Hipercard",VLOOKUP($C$11,'Taxas Bandeira'!A:N,8,0),0))) -> 0.0233372 | D5: =IF($G$2="Sim",C5+0%,C5+H5) -> 0.0233372 | E5: =IFERROR('Simulador Eco Circ Verde'!C23/'Simulador Eco Circ Verde'!$C$24,0) -> 0.76923077 | F5: ='Simulador Eco Circ Verde'!E23 -> 7 | H5: =0.5% -> 0.005
C8: =IF(G2="Sim",'Simulador Eco Circ Verde'!C27,0%) -> 0.0299
B10: Bandeira | C10: ='Simulador Eco Circ Verde'!C17 -> Visa/Master
B11: Estabelecimento | C11: ='Simulador Eco Circ Verde'!B9 -> Comercio varejista de vestuário, acessórios, calçados, roupas íntimas, etc

Sheet Antecipação
J2: Adquirência (Antecipação)
J3: Antecipação | K3: =K25 -> 0.0299
J4: Crédito à Vista | K4: =K26 -> 0.0101566
J5: Crédito 2-6x | K5: =K27 -> 0.0168586
J6: Crédito 7-12x | K6: =K28 -> 0.02005
J7: Valor da Venda | K7: =K29 -> 0.0233372
B8: Dias por Período | C8: Prazo Médio | D8: Taxa Antecipação | E8: Taxa Total | F8: Taxa Crédito | G8: Valor Líquido | J8: Valor Cobrado Cliente | K8: Modalidade | L8: MDR + Antecipação | M8: Valor Parcela Cliente
B9: 30 | C9: =AVERAGE(B9) -> 30 | D9: =($K$25/30)*(C9-1) -> 0.028903333 | E9: =D9+F9 -> 0.045761933 | F9: =K5 -> 0.0168586 | G9: =J10*(1-E9) -> 0 | J9: ='Simulador Eco Circ Verde'!C20 -> 0 | K9: Débito | L9: =$K$26 -> 0.0101566 | M9: =(1-L9)*J9 -> 0
B10: 60 | C10: =AVERAGE(B9:B10) -> 45 | D10: =($K$25/30)*(C10-1) -> 0.043853333 | E10: =D10+F10 -> 0.063903333 | F10: =K6 -> 0.02005 | G10: =J11*(1-E10) -> 0 | J10: =J9 -> 0 | K10: Crédito à vista | L10: =E9 -> 0.045761933 | M10: =G9 -> 0
B11: 90 | C11: =AVERAGE(B9:B11) -> 60 | D11: =($K$25/30)*(C11-1) -> 0.058803333 | E11: =D11+F11 -> 0.078853333 | F11: =K6 -> 0.02005 | G11: =J12*(1-E11) -> 0 | J11: =J10 -> 0 | K11: 2 | L11: =E10 -> 0.063903333 | M11: =G10 -> 0
B12: 120 | C12: =AVERAGE(B9:B12) -> 75 | D12: =($K$25/30)*(C12-1) -> 0.073753333 | E12: =D12+F12 -> 0.093803333 | F12: =K6 -> 0.02005 | G12: =J13*(1-E12) -> 0 | J12: =J10 -> 0 | K12: 3 | L12: =E11 -> 0.078853333 | M12: =G11 -> 0
B13: 150 | C13: =AVERAGE(B9:B13) -> 90 | D13: =($K$25/30)*(C13-1) -> 0.088703333 | E13: =D13+F13 -> 0.10875333 | F13: =K6 -> 0.02005 | G13: =J14*(1-E13) -> 0 | J13: =J10 -> 0 | K13: 4 | L13: =E12 -> 0.093803333 | M13: =G12 -> 0
B14: 180 | C14: =AVERAGE(B9:B14) -> 105 | D14: =($K$25/30)*(C14-1) -> 0.10365333 | E14: =D14+F14 -> 0.12370333 | F14: =K6 -> 0.02005 | G14: =J15*(1-E14) -> 0 | J14: =J10 -> 0 | K14: 5 | L14: =E13 -> 0.10875333 | M14: =G13 -> 0
B15: 210 | C15: =AVERAGE(B9:B15) -> 120 | D15: =($K$25/30)*(C15-1) -> 0.11860333 | E15: =D15+F15 -> 0.14194053 | F15: =K7 -> 0.0233372 | G15: =J16*(1-E15) -> 0 | J15: =J10 -> 0 | K15: 6 | L15: =E14 -> 0.12370333 | M15: =G14 -> 0
B16: 240 | C16: =AVERAGE(B9:B16) -> 135 | D16: =($K$25/30)*(C16-1) -> 0.13355333 | E16: =D16+F16 -> 0.15689053 | F16: =K7 -> 0.0233372 | G16: =J17*(1-E16) -> 0 | J16: =J10 -> 0 | K16: 7 | L16: =E15 -> 0.14194053 | M16: =G15 -> 0
B17: 270 | C17: =AVERAGE(B9:B17) -> 150 | D17: =($K$25/30)*(C17-1) -> 0.14850333 | E17: =D17+F17 -> 0.17184053 | F17: =K7 -> 0.0233372 | G17: =J18*(1-E17) -> 0 | J17: =J10 -> 0 | K17: 8 | L17: =E16 -> 0.15689053 | M17: =G16 -> 0
B18: 300 | C18: =AVERAGE(B9:B18) -> 165 | D18: =($K$25/30)*(C18-1) -> 0.16345333 | E18: =D18+F18 -> 0.18679053 | F18: =K7 -> 0.0233372 | G18: =J19*(1-E18) -> 0 | J18: =J10 -> 0 | K18: 9 | L18: =E17 -> 0.17184053 | M18: =G17 -> 0
B19: 330 | C19: =AVERAGE(B9:B19) -> 180 | D19: =($K$25/30)*(C19-1) -> 0.17840333 | E19: =D19+F19 -> 0.20174053 | F19: =K7 -> 0.0233372 | G19: =J20*(1-E19) -> 0 | J19: =J10 -> 0 | K19: 10 | L19: =E18 -> 0.18679053 | M19: =G18 -> 0
B20: 360 | C20: =AVERAGE(B9:B20) -> 195 | D20: =($K$25/30)*(C20-1) -> 0.19335333 | E20: =D20+F20 -> 0.21669053 | F20: =K7 -> 0.0233372 | G20: =J21*(1-E20) -> 0 | J20: =J10 -> 0 | K20: 11 | L20: =E19 -> 0.20174053 | M20: =G19 -> 0
J21: =J10 -> 0 | K21: 12 | L21: =E20 -> 0.21669053 | M21: =G20 -> 0
M22: =M9 -> 0
K25: ='Taxa Adquirência'!C8 -> 0.0299
K26: ='Taxa Adquirência'!D2 -> 0.0101566
K27: ='Taxa Adquirência'!D3 -> 0.0168586
K28: ='Taxa Adquirência'!D4 -> 0.02005
K29: ='Taxa Adquirência'!D5 -> 0.0233372
J31: ='Simulador Eco Circ Verde'!C21 -> 1000 | L31: =$K$26 -> 0.0101566 | M31: =(1-L31)*J31 -> 989.8434
B32: 30 | C32: =AVERAGE(B32) -> 30 | D32: =($K$25/30)*(C32-1) -> 0.028903333 | E32: =D32+F32 -> 0.045761933 | F32: =K27 -> 0.0168586 | G32: =J32*(1-E32) -> 954.23807 | J32: =J31 -> 1000 | L32: =E32 -> 0.045761933 | M32: =G32 -> 954.23807
B33: 60 | C33: =AVERAGE(B32:B33) -> 45 | D33: =($K$25/30)*(C33-1) -> 0.043853333 | E33: =D33+F33 -> 0.063903333 | F33: =K28 -> 0.02005 | G33: =J33*(1-E33) -> 936.09667 | J33: =J32 -> 1000 | K33: 2 x | L33: =E33 -> 0.063903333 | M33: =G33 -> 936.09667
B34: 90 | C34: =AVERAGE(B32:B34) -> 60 | D34: =($K$25/30)*(C34-1) -> 0.058803333 | E34: =D34+F34 -> 0.078853333 | F34: =K28 -> 0.02005 | G34: =J34*(1-E34) -> 921.14667 | J34: =J32 -> 1000 | K34: 3 x | L34: =E34 -> 0.078853333 | M34: =G34 -> 921.14667
B35: 120 | C35: =AVERAGE(B32:B35) -> 75 | D35: =($K$25/30)*(C35-1) -> 0.073753333 | E35: =D35+F35 -> 0.093803333 | F35: =K28 -> 0.02005 | G35: =J35*(1-E35) -> 906.19667 | J35: =J32 -> 1000 | K35: 4 x | L35: =E35 -> 0.093803333 | M35: =G35 -> 906.19667
B36: 150 | C36: =AVERAGE(B32:B36) -> 90 | D36: =($K$25/30)*(C36-1) -> 0.088703333 | E36: =D36+F36 -> 0.10875333 | F36: =K28 -> 0.02005 | G36: =J36*(1-E36) -> 891.24667 | J36: =J32 -> 1000 | K36: 5 x | L36: =E36 -> 0.10875333 | M36: =G36 -> 891.24667
B37: 180 | C37: =AVERAGE(B32:B37) -> 105 | D37: =($K$25/30)*(C37-1) -> 0.10365333 | E37: =D37+F37 -> 0.12370333 | F37: =K28 -> 0.02005 | G37: =J37*(1-E37) -> 876.29667 | J37: =J32 -> 1000 | K37: 6 x | L37: =E37 -> 0.12370333 | M37: =G37 -> 876.29667
B38: 210 | C38: =AVERAGE(B32:B38) -> 120 | D38: =($K$25/30)*(C38-1) -> 0.11860333 | E38: =D38+F38 -> 0.14194053 | F38: =K29 -> 0.0233372 | G38: =J38*(1-E38) -> 858.05947 | J38: =J32 -> 1000 | K38: 7 x | L38: =E38 -> 0.14194053 | M38: =G38 -> 858.05947
B39: 240 | C39: =AVERAGE(B32:B39) -> 135 | D39: =($K$25/30)*(C39-1) -> 0.13355333 | E39: =D39+F39 -> 0.15689053 | F39: =K29 -> 0.0233372 | G39: =J39*(1-E39) -> 843.10947 | J39: =J32 -> 1000 | K39: 8 x | L39: =E39 -> 0.15689053 | M39: =G39 -> 843.10947
B40: 270 | C40: =AVERAGE(B32:B40) -> 150 | D40: =($K$25/30)*(C40-1) -> 0.14850333 | E40: =D40+F40 -> 0.17184053 | F40: =K29 -> 0.0233372 | G40: =J40*(1-E40) -> 828.15947 | J40: =J32 -> 1000 | K40: 9 x | L40: =E40 -> 0.17184053 | M40: =G40 -> 828.15947
B41: 300 | C41: =AVERAGE(B32:B41) -> 165 | D41: =($K$25/30)*(C41-1) -> 0.16345333 | E41: =D41+F41 -> 0.18679053 | F41: =K29 -> 0.0233372 | G41: =J41*(1-E41) -> 813.20947 | J41: =J32 -> 1000 | K41: 10 x | L41: =E41 -> 0.18679053 | M41: =G41 -> 813.20947
B42: 330 | C42: =AVERAGE(B32:B42) -> 180 | D42: =($K$25/30)*(C42-1) -> 0.17840333 | E42: =D42+F42 -> 0.20174053 | F42: =K29 -> 0.0233372 | G42: =J42*(1-E42) -> 798.25947 | J42: =J32 -> 1000 | K42: 11 x | L42: =E42 -> 0.20174053 | M42: =G42 -> 798.25947
B43: 360 | C43: =AVERAGE(B32:B43) -> 195 | D43: =($K$25/30)*(C43-1) -> 0.19335333 | E43: =D43+F43 -> 0.21669053 | F43: =K29 -> 0.0233372 | G43: =J43*(1-E43) -> 783.30947 | J43: =J32 -> 1000 | K43: 12 x | L43: =E43 -> 0.21669053 | M43: =G43 -> 783.30947
M44: =M32 -> 954.23807
...

Sheet Outros Serviços
B2: Serviço | C2: Receita | D2: Custo
B3: Cartão de Crédito | C3: 0.03 | D3: -
B4: Boleto Recarga | C4: 3 | D4: 0.9
B5: Boleto Cobrança Liquidado | C5: 3 | D5: 0.9
B6: TED | C6: 5.9 | D6: 1.77
B7: Saque Banco 24Horas | C7: 9 | D7: 2.7

Sheet Taxas Bandeira
A2: - | C2: 0.009865 | D2: 0.013377 | E2: 0.016077 | F2: 0.021127 | G2: 0.013125 | H2: 0.017125 | I2: 0.010135 | J2: 0 | K2: 0.0126526 | L2: 0.0170726 | M2: 0.0097786 | N2: 0.0076078
A3: - | C3: 0.009865 | D3: 0.013377 | E3: 0.016077 | F3: 0.021127 | G3: 0.024125 | H3: 0.027125 | I3: 0.009925 | J3: 0 | K3: 0.0178126 | L3: 0.0215126 | M3: 0.0082126 | N3: 0.0057958
A4: - | C4: 0.009865 | D4: 0.013377 | E4: 0.016077 | F4: 0.021127 | G4: 0.025625 | H4: 0.028625 | I4: 0.017125 | J4: 0 | K4: 0.0126526 | L4: 0.0170726 | M4: 0.0097786 | N4: 0.0076494
A5: - | C5: 0.009865 | D5: 0.013377 | E5: 0.016077 | F5: 0.021127 | G5: 0.025625 | H5: 0.028625 | I5: 0.017125 | J5: 0 | K5: 0.0162926 | L5: 0.0207126 | M5: 0.0134186 | N5: 0.0087098
A6: - | C6: 0.009865 | D6: 0.013377 | E6: 0.016077 | F6: 0.021127 | G6: 0.025625 | H6: 0.028625 | I6: 0.017125 | J6: 0 | K6: 0.01765 | L6: 0.0209372 | M6: 0.0144586 | N6: 0.0078574
A7: - | C7: 0.01043 | D7: 0.013377 | E7: 0.016077 | F7: 0.021127 | G7: 0.024125 | H7: 0.027125 | I7: 0.013025 | J7: 0 | K7: 0.0178126 | L7: 0.0215126 | M7: 0.0100726 | N7: 0.0069958
A8: - | C8: 0.012905 | D8: 0.013377 | E8: 0.016077 | F8: 0.021127 | G8: 0.025625 | H8: 0.028625 | I8: 0.017125 | J8: 0 | K8: 0.01765 | L8: 0.0209372 | M8: 0.0144586 | N8: 0.0078574
A9: - | C9: 0.014394 | D9: 0.013377 | E9: 0.016077 | F9: 0.021127 | G9: 0.016125 | H9: 0.023125 | I9: 0.010525 | J9: 0 | K9: 0.0066526 | L9: 0.0086726 | M9: 0.0085726 | N9: 0.0076078
A10: - | C10: 0.014355 | D10: 0.018917 | E10: 0.019067 | F10: 0.019317 | G10: 0.013125 | H10: 0.017125 | I10: 0.010135 | J10: 0 | K10: 0.014283 | L10: 0.018283 | M10: 0.011689 | N10: 0.008699
A11: Mini Mercado e Supermercado | C11: 0.010377 | D11: 0.017177 | E11: 0.021092 | F11: 0.026142 | G11: 0.024125 | H11: 0.027125 | I11: 0.014125 | J11: 0 | K11: 0.019656 | L11: 0.0229432 | M11: 0.0157086 | N11: 0.0064066
A12: Padaria | C12: 0.010377 | D12: 0.017177 | E12: 0.021092 | F12: 0.026142 | G12: 0.025625 | H12: 0.028625 | I12: 0.017125 | J12: 0 | K12: 0.019656 | L12: 0.0229432 | M12: 0.0159786 | N12: 0.0070186
A13: - | C13: 0.010377 | D13: 0.017177 | E13: 0.021092 | F13: 0.026142 | G13: 0.025625 | H13: 0.028625 | I13: 0.017125 | J13: 0 | K13: 0.019656 | L13: 0.0229432 | M13: 0.0159786 | N13: 0.0078622
... A60: - | C60: 0.013305 | D60: 0.022477 | E60: 0.025177 | F60: 0.030227 | G60: 0.025625 | H60: 0.028625 | I60: 0.017125 | J60: 0 | K60: 0.02129 | L60: 0.0245772 | M60: 0.0180986 | N60: 0.0089594

Sheet Outros
K1: Até 30 mil | L1: Até 50 mil | M1: Até 75 mil | N1: Acima de 75 mil | P1: ='Simulador Eco Circ Verde'!C24 -> 26000
A2: Básico | B2: Sim | C2: Visa/Master | D2: Comercio varejista de vestuário, acessórios, calçados, roupas íntimas, etc | E2: 2 | F2: 7 | G2: 500 | H2: 0 | I2: Cepisa | J2: =IF(P2=0%,"",P2) -> 0.0299 | K2: =K3+0.1% -> 0.0199 | L2: =L3+0.1% -> 0.0199 | M2: =M3+0.1% -> 0.0199 | N2: =N3+0.1% -> 0.0199 | P2: 0.0299
A3: Ecoa | B3: Não | C3: Elo | D3: Comércio varejista de protese dentaria, odontologica, etc | E3: 3 | F3: 8 | G3: =G2+100 -> 600 | H3: 0.005 | I3: Enel CE | J3: =IF(P3=0%,"",P3) -> 0.0249 | K3: 0.0189 | L3: =L4+0.1% -> 0.0189 | M3: =M4+0.1% -> 0.0189 | N3: =N4+0.1% -> 0.0189 | P3: =P2-0.5% -> 0.0249
C4: Hipercard | D4: Clínicas estéticas e similares, tratamento beleza, etc | E4: 4 | F4: 9 | G4: =G3+100 -> 700 | H4: =H3+0.5% -> 0.01 | I4: Enel SP | J4: =IF(P4=0%,"",P4) -> 0.0199 | K4: 0.0179 | L4: =L5+0.1% -> 0.0179 | M4: =M5+0.1% -> 0.0179 | N4: =N5+0.1% -> 0.0179 | P4: =P3-0.5% -> 0.0199
D5: Comercio varejista de produtos medicos, ortopedicos, cosmeticos, perfumaria, otica, odontologia, tecidos, animais vivos, loja departamento, peças veiculos e motos | E5: 5 | F5: 10 | G5: =G4+100 -> 800 | H5: =H4+0.5% -> 0.015 | I5: Enel RJ | J5: =IF(P5=0%,"",P5) -> 0.0149 | L5: 0.0169 | M5: =M6+0.1% -> 0.0169 | N5: =N6+0.1% -> 0.0169 | P5: =P4-0.5% -> 0.0149
D6: Comercio varejista de material de construção, eletrico, etc | E6: 6 | F6: 11 | G6: =G5+100 -> 900 | H6: =H5+0.5% -> 0.02 | I6: EDP | J6: =IF(P6=0%,"",P6) -> 0.0099 | L6: 0.0159 | M6: =M7+0.1% -> 0.0159 | N6: =N7+0.1% -> 0.0159 | P6: =P5-0.5% -> 0.0099
D7: Mini Mercado e Supermercado | F7: 12 | G7: =G6+100 -> 1000 | H7: =H6+0.5% -> 0.025 | I7: CEB | J7: =IF(P7=0%,"",P7) | L7: 0.0149 | M7: =M8+0.1% -> 0.0149 | N7: =N8+0.1% -> 0.0149 | P7: 0
D8: Padaria | G8: =G7+100 -> 1100 | H8: =H7+0.5% -> 0.03 | I8: RGE | J8: =IF(P8=0%,"",P8) | M8: =M9+0.1% -> 0.0139 | N8: =N9+0.1% -> 0.0139 | P8: =IF($P$1<=30000,K8,IF($P$1<=50000,L8,IF($P$1<=75000,M8,N8))) -> 0
D9: Bar e Restaurante | G9: =G8+100 -> 1200 | H9: =H8+0.5% -> 0.035 | I9: CPFL Paulista | J9: =IF(P9=0%,"",P9) | M9: =M10+0.1% -> 0.0129 | N9: =N10+0.1% -> 0.0129 | P9: =IF($P$1<=30000,K9,IF($P$1<=50000,L9,IF($P$1<=75000,M9,N9))) -> 0
D10: Hotel | G10: =G9+100 -> 1300 | H10: =H9+0.5% -> 0.04 | I10: Cemig | J10: =IF(P10=0%,"",P10) | M10: 0.0119 | N10: =N11+0.1% -> 0.0119 | P10: =IF($P$1<=30000,K10,IF($P$1<=50000,L10,IF($P$1<=75000,M10,N10))) -> 0
G11: =G10+100 -> 1400 | H11: =H10+0.5% -> 0.045 | I11: Light | J11: =IF(P11=0%,"",P11) | N11: =N12+0.1% -> 0.0109 | P11: =IF($P$1<=30000,K11,IF($P$1<=50000,L11,IF($P$1<=75000,M11,N11))) -> 0
G12: =G11+100 -> 1500 | H12: =H11+0.5% -> 0.05 | J12: =IF(P12=0%,"",P12) | N12: 0.0099 | P12: =IF($P$1<=30000,K12,IF($P$1<=50000,L12,IF($P$1<=75000,M12,N12))) -> 0
G13: =G12+100 -> 1600 | H13: =H12+0.5% -> 0.055
G14: =G13+100 -> 1700 | H14: =H13+0.5% -> 0.06
G15: =G14+100 -> 1800 | H15: =H14+0.5% -> 0.065
G16: =G15+100 -> 1900 | H16: =H15+0.5% -> 0.07
G17: =G16+100 -> 2000 | H17: =H16+0.5% -> 0.075
G18: =G17+100 -> 2100 | H18: =H17+0.5% -> 0.08
G19: =G18+100 -> 2200 | H19: =H18+0.5% -> 0.085
G20: =G19+100 -> 2300 | H20: =H19+0.5% -> 0.09
G21: =G20+100 -> 2400 | H21: =H20+0.5% -> 0.095
G22: =G21+100 -> 2500 | H22: =H21+0.5% -> 0.1
G23: =G22+100 -> 2600 | H23: =H22+0.5% -> 0.105
G24: =G23+100 -> 2700 | H24: =H23+0.5% -> 0.11
... G32: =G31+100 -> 3500 | H32: =H31+0.5% -> 0.15
G33: =G32+100 -> 3600
G34: =G33+100 -> 3700
G35: =G34+100 -> 3800
G36: =G35+100 -> 3900
G37: =G36+100 -> 4000
